Workbook

Sheet Cover_Page
F4: SHRISHTI RAIZADA
F5: MBA24253
F6: IAPM Analysis
F7: Power Grid Corporation Of India Ltd

Sheet Industry_Analysis
A1: Market Overview | E1: Industry Drivers
A2: Metric | B2: Value | E2: Driver | F2: Impact
A3: India Peak Power Demand (GW) | B3: 250 | E3: Rising electricity demand | F3: High
A4: Transmission Network (circuit km) | B4: 4,70,000+ | E4: Renewable integration | F4: High
A5: PGCIL Market Share (%) | B5: 85 | E5: Government infra push | F5: Medium
A6: Expected Power Demand CAGR (2024-2030) | B6: 6-7% | E6: EV adoption | F6: Medium
A7: Renewable Capacity Target (2030, GW) | B7: 500
E8: Risks
A9: Regulation & Policy | E9: Risk | F9: Severity
A10: Aspect | B10: Details | E10: Tariff cut by regulator | F10: High
A11: Tariff Regulation | B11: Long-term regulated tariff (CERC) | E11: Execution delays in projects | F11: Medium
A12: Regulatory Body | B12: CERC (Central Electricity Regulatory Commission) | E12: Competition from private players | F12: Medium
A13: Key Scheme | B13: Green Energy Corridors | E13: Renewable intermittency | F13: Medium
A14: Government Focus | B14: Integration of renewables, transmission infra expansion
E15: Outlook
A16: Competition | E16: Period | F16: Outlook
A17: Company | B17: Market Share (%) | C17: Strength | E17: Short Term (1-3 yrs) | F17: Stable regulated returns
A18: Power Grid Corporation of India (PGCIL) | B18: 85 | C18: National monopoly, regulated returns | E18: Medium Term (3-5 yrs) | F18: Expansion with renewable corridors
A19: Adani Transmission | B19: 10 | C19: Aggressive private expansion | E19: Long Term (5-10 yrs) | F19: Strategic role in India’s green energy transition
A20: Sterlite Power | B20: 3 | C20: Innovative projects, niche presence

Sheet Macro
A1: Year | B1: Industry Sales | C1: Industry Growth Rate | D1: GDP | E1: GDP Growth | F1: Power Grid Corporation Sales | G1: Market Share | H1: Inflation | I1: GDP Growth Rate | J1: Inflation Growth Rate | K1: Inflation | L1: GDP Growth Rate (IMF) | N1: Parameter | O1: 2025-26 | P1: 2026-27 | Q1: 2027-28 | R1: 2028-29 | S1: 2029-30
A2: 2013 | B2: 234618.99 | D2: 9944013 | F2: 13163.9 | G2: =F2/B2 -> 0.056107564 | H2: 9.4 | I2: =9.4/100 -> 0.094 | J2: 6.4 | K2: =J2/100 -> 0.064 | L2: =I2/100 -> 0.00094 | N2: Inflation Rate | O2: 4.1 | P2: 4 | Q2: 4 | R2: 4 | S2: 4
A3: 2014 | B3: 262332.13 | C3: =(B3-B2)/B2 -> 0.11811977 | D3: 11233522 | E3: =(D3-D2)/D2 -> 0.12967692 | F3: 15675.43 | G3: =F3/B3 -> 0.059754137 | H3: 5.8 | I3: =5.8/100 -> 0.058 | J3: 7.4 | K3: =J3/100 -> 0.074 | L3: =I3/100 -> 0.00058 | N3: GDP Growth rate (IMF) | O3: 6.3 | P3: 6.5 | Q3: 6.5 | R3: 6.5 | S3: 6.5
A4: 2015 | B4: 277760.39 | C4: =(B4-B3)/B3 -> 0.058811934 | D4: 12467959 | E4: =(D4-D3)/D3 -> 0.10988869 | F4: 17658.51 | G4: =F4/B4 -> 0.063574616 | H4: 4.9 | I4: =H4/100 -> 0.049 | J4: 8 | K4: =J4/100 -> 0.08 | L4: =I4/100 -> 0.00049
A5: 2016 | B5: 312391.14 | C5: =(B5-B4)/B4 -> 0.1246785 | D5: 13771874 | E5: =(D5-D4)/D4 -> 0.10458127 | F5: 20652.08 | G5: =F5/B5 -> 0.066109685 | H5: 4.5 | I5: =H5/100 -> 0.045 | J5: 8.3 | K5: =J5/100 -> 0.083 | L5: =I5/100 -> 0.00045
A6: 2017 | B6: 346635.25 | C6: =(B6-B5)/B5 -> 0.10961934 | D6: 15391669 | E6: =(D6-D5)/D5 -> 0.11761616 | F6: 25697.44 | G6: =F6/B6 -> 0.074133949 | H6: 3.6 | I6: =H6/100 -> 0.036 | J6: 6.8 | K6: =J6/100 -> 0.068 | L6: =I6/100 -> 0.00036
A7: 2018 | B7: 361556.78 | C7: =(B7-B6)/B6 -> 0.043046776 | D7: 17090042 | E7: =(D7-D6)/D6 -> 0.11034365 | F7: 29953.62 | G7: =F7/B7 -> 0.082846241 | H7: 3.4 | I7: =H7/100 -> 0.034 | J7: 6.5 | K7: =J7/100 -> 0.065 | L7: =I7/100 -> 0.00034 | N7: Industry Growth Rate (Based on GDP) | O7: =O3*$K$34 -> 7.3780095 | P7: =P3*$K$34 -> 7.612232 | Q7: =Q3*$K$34 -> 7.612232 | R7: =R3*$K$34 -> 7.612232 | S7: =S3*$K$34 -> 7.612232
A8: 2019 | B8: 379720.48 | C8: =(B8-B7)/B7 -> 0.050237476 | D8: 18899668 | E8: =(D8-D7)/D7 -> 0.10588774 | F8: 35059.12 | G8: =F8/B8 -> 0.092328757 | H8: 4.8 | I8: =H8/100 -> 0.048 | J8: 3.9 | K8: =J8/100 -> 0.039 | L8: =I8/100 -> 0.00048 | N8: Industry Growth Rate (Based on Inflation) | O8: =O2*$U$34 -> 7.8685567 | P8: =P2*$U$34 -> 7.6766407 | Q8: =Q2*$U$34 -> 7.6766407 | R8: =R2*$U$34 -> 7.6766407 | S8: =S2*$U$34 -> 7.6766407
A9: 2020 | B9: 408525.96 | C9: =(B9-B8)/B8 -> 0.075859696 | D9: 20103593 | E9: =(D9-D8)/D8 -> 0.063700854 | F9: 37743.54 | G9: =F9/B9 -> 0.092389575 | H9: 6.2 | I9: =H9/100 -> 0.062 | J9: -5.8 | K9: =J9/100 -> -0.058 | L9: =I9/100 -> 0.00062
A10: 2021 | B10: 370975.85 | C10: =(B10-B9)/B9 -> -0.091916093 | D10: 19854096 | E10: =(D10-D9)/D9 -> -0.012410568 | F10: 39639.79 | G10: =F10/B10 -> 0.10685275 | H10: 5.5 | I10: =H10/100 -> 0.055 | J10: 9.7 | K10: =J10/100 -> 0.097 | L10: =I10/100 -> 0.00055
A11: 2022 | B11: 438241.45 | C11: =(B11-B10)/B10 -> 0.1813207 | D11: 23597399 | E11: =(D11-D10)/D10 -> 0.18854057 | F11: 41621.64 | G11: =F11/B11 -> 0.09497422 | H11: 6.7 | I11: =H11/100 -> 0.067 | J11: 7.6 | K11: =J11/100 -> 0.076 | L11: =I11/100 -> 0.00067 | N11: Industry Sales | O11: =B14*(1+O7%) -> 687706.28 | P11: =O11*(1+P7%) -> 740056.08 | Q11: =P11*(1+Q7%) -> 796390.87 | R11: =Q11*(1+R7%) -> 857013.99 | S11: =R11*(1+S7%) -> 922251.88
A12: 2023 | B12: 578325.96 | C12: =(B12-B11)/B11 -> 0.31965144 | D12: 26890473 | E12: =(D12-D11)/D11 -> 0.13955242 | F12: 45603.11 | G12: =F12/B12 -> 0.078853645 | H12: 5.4 | I12: =H12/100 -> 0.054 | J12: 9.2 | K12: =J12/100 -> 0.092 | L12: =I12/100 -> 0.00054 | N12: Forecasted Sales (Power Grid Corporation) | O12: =O11*$E$19 -> 59996.415 | P12: =P11*$E$19 -> 64563.482 | Q12: =Q11*$E$19 -> 69478.204 | R12: =R11*$E$19 -> 74767.046 | S12: =S11*$E$19 -> 80458.487
A13: 2024 | B13: 621259.54 | C13: =(B13-B12)/B12 -> 0.074237684 | D13: 30122956 | E13: =(D13-D12)/D12 -> 0.12020924 | F13: 45843.1 | G13: =F13/B13 -> 0.073790577 | H13: 4.7 | I13: =H13/100 -> 0.047 | J13: 6.5 | K13: =J13/100 -> 0.065 | L13: =I13/100 -> 0.00047
A14: 2025 | B14: 640453.56 | C14: =(B14-B13)/B13 -> 0.030895332 | D14: 33068000 | E14: =(D14-D13)/D13 -> 0.097767434 | F14: 45792.32 | G14: =F14/B14 -> 0.071499829 | H14: 4.2 | I14: =H14/100 -> 0.042 | J14: 6.2 | K14: =J14/100 -> 0.062 | L14: =I14/100 -> 0.00042 | N14: % Change | P14: =(P12-O12)/O12 -> 0.07612232 | Q14: =(Q12-P12)/P12 -> 0.07612232 | R14: =(R12-Q12)/Q12 -> 0.07612232 | S14: =(S12-R12)/R12 -> 0.07612232
J17: SUMMARY OUTPUT | L17: GDP | T17: SUMMARY OUTPUT | V17: Inflation
C19: Average Market Share | E19: =AVERAGE(G8:G14) -> 0.087241336 | J19: Regression Statistics | T19: Regression Statistics
J20: Multiple R | K20: 0.63691222 | T20: Multiple R | U20: 0.72374705
J21: R Square | K21: 0.40565718 | T21: R Square | U21: 0.5238098
J22: Adjusted R Square | K22: 0.30565718 | T22: Adjusted R Square | U22: 0.4238098
J23: Standard Error | K23: 0.11014352 | T23: Standard Error | U23: 0.098589504
J24: Observations | K24: 11 | T24: Observations | U24: 11
J26: ANOVA | T26: ANOVA
K27: df | L27: SS | M27: MS | N27: F | O27: Significance F | U27: df | V27: SS | W27: MS | X27: F | Y27: Significance F
J28: Regression | K28: 1 | L28: 0.082801856 | M28: 0.082801856 | N28: 6.8253063 | O28: 0.028153764 | T28: Regression | U28: 1 | V28: 0.10691891 | W28: 0.10691891 | X28: 11.000012 | Y28: 0.0089884914
J29: Residual | K29: 10 | L29: 0.12131596 | M29: 0.012131596 | T29: Residual | U29: 10 | V29: 0.097198903 | W29: 0.0097198903
J30: Total | K30: 11 | L30: 0.20411781 | T30: Total | U30: 11 | V30: 0.20411781
K32: Coefficients | L32: Standard Error | M32: t Stat | N32: P-value | O32: Lower 95% | P32: Upper 95% | Q32: Lower 95.0% | R32: Upper 95.0% | U32: Coefficients | V32: Standard Error | W32: t Stat | X32: P-value | Y32: Lower 95% | Z32: Upper 95% | AA32: Lower 95.0% | AB32: Upper 95.0%
J33: Intercept | K33: 0 | L33: #N/A | M33: #N/A | N33: #N/A | O33: #N/A | P33: #N/A | Q33: #N/A | R33: #N/A | T33: Intercept | U33: 0 | V33: #N/A | W33: #N/A | X33: #N/A | Y33: #N/A | Z33: #N/A | AA33: #N/A | AB33: #N/A
J34: X Variable 1 | K34: 1.1711126 | L34: 0.44826784 | M34: 2.6125287 | N34: 0.025928036 | O34: 0.17230962 | P34: 2.1699156 | Q34: 0.17230962 | R34: 2.1699156 | T34: X Variable 1 | U34: 1.9191602 | V34: 0.57864825 | W34: 3.3166266 | X34: 0.0077916863 | Y34: 0.62985153 | Z34: 3.2084688 | AA34: 0.62985153 | AB34: 3.2084688

Sheet GDP_Regression
A1: SUMMARY OUTPUT
A3: Regression Statistics
A4: Multiple R | B4: 0.72374705
A5: R Square | B5: 0.5238098
A6: Adjusted R Square | B6: 0.4238098
A7: Standard Error | B7: 0.098589504
A8: Observations | B8: 11
A10: ANOVA
B11: df | C11: SS | D11: MS | E11: F | F11: Significance F
A12: Regression | B12: 1 | C12: 0.10691891 | D12: 0.10691891 | E12: 11.000012 | F12: 0.0089884914
A13: Residual | B13: 10 | C13: 0.097198903 | D13: 0.0097198903
A14: Total | B14: 11 | C14: 0.20411781
B16: Coefficients | C16: Standard Error | D16: t Stat | E16: P-value | F16: Lower 95% | G16: Upper 95% | H16: Lower 95.0% | I16: Upper 95.0%
A17: Intercept | B17: 0 | C17: #N/A | D17: #N/A | E17: #N/A | F17: #N/A | G17: #N/A | H17: #N/A | I17: #N/A
A18: X Variable 1 | B18: 1.9191602 | C18: 0.57864825 | D18: 3.3166266 | E18: 0.0077916863 | F18: 0.62985153 | G18: 3.2084688 | H18: 0.62985153 | I18: 3.2084688

Sheet Inflation_Regression
A1: SUMMARY OUTPUT
A3: Regression Statistics
A4: Multiple R | B4: 0.63691222
A5: R Square | B5: 0.40565718
A6: Adjusted R Square | B6: 0.30565718
A7: Standard Error | B7: 0.11014352
A8: Observations | B8: 11
A10: ANOVA
B11: df | C11: SS | D11: MS | E11: F | F11: Significance F
A12: Regression | B12: 1 | C12: 0.082801856 | D12: 0.082801856 | E12: 6.8253063 | F12: 0.028153764
A13: Residual | B13: 10 | C13: 0.12131596 | D13: 0.012131596
A14: Total | B14: 11 | C14: 0.20411781
B16: Coefficients | C16: Standard Error | D16: t Stat | E16: P-value | F16: Lower 95% | G16: Upper 95% | H16: Lower 95.0% | I16: Upper 95.0%
A17: Intercept | B17: 0 | C17: #N/A | D17: #N/A | E17: #N/A | F17: #N/A | G17: #N/A | H17: #N/A | I17: #N/A
A18: X Variable 1 | B18: 1.1711126 | C18: 0.44826784 | D18: 2.6125287 | E18: 0.025928036 | F18: 0.17230962 | G18: 2.1699156 | H18: 0.17230962 | I18: 2.1699156

Sheet DCF
A1: Unlevered Free Cash Flow (Cr) | G1: Projections
A2: Projection Year | G2: 1 | H2: 2 | I2: 3 | J2: 4 | K2: 5 | L2: 6 | M2: 7
A3: Fiscal Year | B3: Mar-2021 | C3: Mar-2022 | D3: Mar-2023 | E3: 45352 | F3: Mar-2025 | G3: 46082 | H3: 46447 | I3: 46813 | J3: 47178 | K3: 47543 | L3: 47908 | M3: 48274
A5: Unlevered Free Cash Flow | B5: =FCFF_Projections!B21 -> 15424.45 | C5: =FCFF_Projections!C21 -> 18871.34 | D5: =FCFF_Projections!D21 -> 41104.2 | E5: =FCFF_Projections!E21 -> 34370.16 | F5: =FCFF_Projections!F21 -> 23931.284 | G5: =FCFF_Projections!G21 -> 30166.924 | H5: =FCFF_Projections!H21 -> 31006.938 | I5: =FCFF_Projections!I21 -> 32966.572 | ... M5: =FCFF_Projections!M21 -> 17547.917
A8: Present Value of Free Cash Flow | G8: =G5/(1+$B$13)^G2 -> 27093.296 | H8: =H5/(1+$B$13)^H2 -> 25010.391 | I8: =I5/(1+$B$13)^I2 -> 23881.753 | J8: =J5/(1+$B$13)^J2 -> 20508.257 | K8: =K5/(1+$B$13)^K2 -> 18391.336 | L8: =L5/(1+$B$13)^L2 -> 17126.221 | M8: =M5/(1+$B$13)^M2 -> 8270.6796
A11: Sum of PV of FCF | B11: =SUM(G8:M8) -> 140281.93
A12: Growth Rate | B12: 0.05
A13: WACC | B13: =WACC!B17 -> 0.11344609
A14: Terminal Value | B14: =(M8*(1+B12))/(B13-B12) -> 136875.47
A15: PV of Terminal Value | B15: =B14/(1+B13)^7 -> 64512.111
A16: Enterprise Value | B16: =B11+B15 -> 204794.04
A17: (+) Cash | B17: ='Balance_Sheet(5 years)'!F43 -> 6419.4
A18: (-) Debt | B18: ='Balance_Sheet(5 years)'!F54 -> 130964.96
A19: (-) Minority Interest | B19: 0
A20: Equity Value | B20: ='Balance_Sheet(5 years)'!F7 -> 92215.65
A21: Diluted Shares Outstanding | B21: 342
A22: Implied Share Price | B22: =B20/B21 -> 269.6364

Sheet FCFF_Projections
G1: Projections
A2: Particulars | B2: Mar-2021 | C2: Mar-2022 | D2: Mar-2023 | E2: 45352 | F2: Mar-2025 | G2: 46082 | H2: 46447 | I2: 46813 | J2: 47178 | K2: 47543 | L2: 47908 | M2: 48274
A3: Revenue | B3: ='Income_Statement(5 years)'!B7 -> 37665.65 | C3: ='Income_Statement(5 years)'!C7 -> 39933.39 | D3: ='Income_Statement(5 years)'!D7 -> 42635.9 | E3: ='Income_Statement(5 years)'!E7 -> 42391.16 | F3: ='Income_Statement(5 years)'!F7 -> 41431.49 | G3: =F3*(1+G25) -> 42462.138 | H3: =G3*(1+H25) -> 43143.366 | I3: =H3*(1+I25) -> 43278.626 | J3: =I3*(1+J25) -> 43510.338 | K3: =J3*(1+K25) -> 44047.78 | L3: =K3*(1+L25) -> 44453.948 | M3: =L3*(1+M25) -> 44788.044
A4: COGS | B4: ='Income_Statement(5 years)'!B10+'Income_Statement(5 years)'!B11+'Income_Statement(5 years)'!B12 -> 3405.03 | C4: ='Income_Statement(5 years)'!C10+'Income_Statement(5 years)'!C11+'Income_Statement(5 years)'!C12 -> 3695.45 | D4: ='Income_Statement(5 years)'!D10+'Income_Statement(5 years)'!D11+'Income_Statement(5 years)'!D12 -> 3707.03 | E4: ='Income_Statement(5 years)'!E10+'Income_Statement(5 years)'!E11+'Income_Statement(5 years)'!E12 -> 3867.02 | F4: ='Income_Statement(5 years)'!F10+'Income_Statement(5 years)'!F11+'Income_Statement(5 years)'!F12 -> 4314 | G4: =G3*G27 -> 3950.9665 | H4: =H3*H27 -> 4037.1784 | I4: =I3*I27 -> 4058.7987 | J4: =J3*J27 -> 4140.0234 | K4: =K3*K27 -> 4225.7653 | L4: =L3*L27 -> 4191.9358 | M4: =M3*M27 -> 4234.6517
A5: Gross Profit | B5: =B3-B4 -> 34260.62 | C5: =C3-C4 -> 36237.94 | D5: =D3-D4 -> 38928.87 | E5: =E3-E4 -> 38524.14 | F5: =F3-F4 -> 37117.49 | G5: =G3-G4 -> 38511.172 | H5: =H3-H4 -> 39106.188 | I5: =I3-I4 -> 39219.827 | ... M5: =M3-M4 -> 40553.392
A6: Operating Expenses
A7: Selling, General, Administrative | B7: ='Income_Statement(5 years)'!B13+'Income_Statement(5 years)'!B14 -> 751.13 | C7: ='Income_Statement(5 years)'!C13+'Income_Statement(5 years)'!C14 -> 839.27 | D7: ='Income_Statement(5 years)'!D13+'Income_Statement(5 years)'!D14 -> 864.21 | E7: ='Income_Statement(5 years)'!E13+'Income_Statement(5 years)'!E14 -> 945.15 | F7: ='Income_Statement(5 years)'!F13+'Income_Statement(5 years)'!F14 -> 989.86 | G7: =G3*G28 -> 912.22041 | H7: =H3*H28 -> 940.15302 | I7: =I3*I28 -> 949.80542 | J7: =J3*J28 -> 969.48188 | K7: =K3*K28 -> 981.33119 | L7: =L3*L28 -> 976.04194 | M7: =M3*M28 -> 987.61529
A8: Total Operating Expenses | B8: =B7 -> 751.13 | C8: =C7 -> 839.27 | D8: =D7 -> 864.21 | E8: =E7 -> 945.15 | F8: =F7 -> 989.86 | G8: =G7 -> 912.22041 | H8: =H7 -> 940.15302 | I8: =I7 -> 949.80542 | ... M8: =M7 -> 987.61529
A9: EBITDA | B9: =B5-B8 -> 33509.49 | C9: =C5-C8 -> 35398.67 | D9: =D5-D8 -> 38064.66 | E9: =E5-E8 -> 37578.99 | F9: =F5-F8 -> 36127.63 | G9: =G5-G8 -> 37598.952 | H9: =H5-H8 -> 38166.035 | I9: =I5-I8 -> 38270.022 | ... M9: =M5-M8 -> 39565.777
A10: Depreciation & Amortization | B10: ='Income_Statement(5 years)'!B23 -> 11711.68 | C10: ='Income_Statement(5 years)'!C23 -> 12550.58 | D10: ='Income_Statement(5 years)'!D23 -> 12858.52 | E10: ='Income_Statement(5 years)'!E23 -> 12558.19 | F10: ='Income_Statement(5 years)'!F23 -> 12352.23 | G10: =Fixed_Assets!G4 -> 10831.875 | H10: =Fixed_Assets!H4 -> 10531.833 | I10: =Fixed_Assets!I4 -> 10158.156 | J10: =Fixed_Assets!J4 -> 9708.2725 | K10: =Fixed_Assets!K4 -> 9237.0002 | L10: =Fixed_Assets!L4 -> 8694.2006 | M10: =Fixed_Assets!M4 -> 8321.7139
A11: Operating Profit (EBIT) | B11: =B9-B10 -> 21797.81 | C11: =C9-C10 -> 22848.09 | D11: =D9-D10 -> 25206.14 | E11: =E9-E10 -> 25020.8 | F11: =F9-F10 -> 23775.4 | G11: =G9-G10 -> 26767.077 | H11: =H9-H10 -> 27634.202 | I11: =I9-I10 -> 28111.866 | ... M11: =M9-M10 -> 31244.063
A12: Operating Taxes | B12: ='Income_Statement(5 years)'!B28 -> 3089.14 | C12: ='Income_Statement(5 years)'!C28 -> 2711.06 | D12: ='Income_Statement(5 years)'!D28 -> 2118.84 | E12: ='Income_Statement(5 years)'!E28 -> 2631.98 | F12: ='Income_Statement(5 years)'!F28 -> 3265.86 | G12: =G11*G29 -> 3142.3955 | H12: =H11*H29 -> 3109.7806 | I12: =I11*I29 -> 3129.1132 | J12: =J11*J29 -> 3350.1178 | K12: =K11*K29 -> 3524.9874 | L12: =L11*L29 -> 3530.7343 | M12: =M11*M29 -> 3593.6254
A13: NOPAT (Net Operating Profit After Taxes) | B13: =B11-B12 -> 18708.67 | C13: =C11-C12 -> 20137.03 | D13: =D11-D12 -> 23087.3 | E13: =E11-E12 -> 22388.82 | F13: =F11-F12 -> 20509.54 | G13: =G11-G12 -> 23624.681 | H13: =H11-H12 -> 24524.421 | I13: =I11-I12 -> 24982.753 | ... M13: =M11-M12 -> 27650.438
A14: (+) Depreciation & Amortization | B14: =B10 -> 11711.68 | C14: =C10 -> 12550.58 | D14: =D10 -> 12858.52 | E14: =E10 -> 12558.19 | F14: =F10 -> 12352.23 | G14: =G10 -> 10831.875 | H14: =H10 -> 10531.833 | I14: =I10 -> 10158.156 | ... M14: =M10 -> 8321.7139
A15: (-) Capital Expenditures | B15: =Fixed_Assets!B5 -> 14499.94 | C15: =Fixed_Assets!C5 -> 5096.37 | D15: =Fixed_Assets!D5 -> 3281.48 | E15: =Fixed_Assets!E5 -> 3492.54 | F15: =Fixed_Assets!F5 -> 5792.6429 | G15: =Fixed_Assets!G5 -> 3918.5665 | H15: =Fixed_Assets!H5 -> 3674.3787 | I15: =Fixed_Assets!I5 -> 3733.4772 | ... M15: =Fixed_Assets!M5 -> 3098.8475
A16: (-) Change in NWC | B16: =C17-B17 -> 495.96 | C16: =D17-C17 -> 8719.9 | D16: =E17-D17 -> -8439.86 | E16: =F17-E17 -> -2915.69 | F16: =G17-F17 -> 3137.8428 | G16: =H17-G17 -> 371.06554 | H16: =I17-H17 -> 374.93799 | I16: =J17-I17 -> -1559.1408 | ... M16: =N17-M17 -> 15325.388
A17: NWC | B17: =B18-B19 -> -15693.2 | C17: =C18-C19 -> -15197.24 | D17: =D18-D19 -> -6477.34 | E17: =E18-E19 -> -14917.2 | F17: =F18-F19 -> -17832.89 | G17: =G18-G19 -> -14695.047 | H17: =H18-H19 -> -14323.982 | I17: =I18-I19 -> -13949.044 | ... M17: =M18-M19 -> -15325.388
A18: Current Assets | B18: =NWC!B6 -> 10768.71 | C18: =NWC!C6 -> 10849.82 | D18: =NWC!D6 -> 16380.31 | E18: =NWC!E6 -> 12543.22 | F18: =NWC!F6 -> 9193.48 | G18: =NWC!G6 -> 12399.616 | H18: =NWC!H6 -> 12650.081 | I18: =NWC!I6 -> 12875.743 | ... M18: =NWC!M6 -> 12861.893
A19: Current Liabilitites | B19: =NWC!B10 -> 26461.91 | C19: =NWC!C10 -> 26047.06 | D19: =NWC!D10 -> 22857.65 | E19: =NWC!E10 -> 27460.42 | F19: =NWC!F10 -> 27026.37 | G19: =NWC!G10 -> 27094.663 | H19: =NWC!H10 -> 26974.063 | I19: =NWC!I10 -> 26824.786 | ... M19: =NWC!M10 -> 28187.281
A21: Unlevered Free Cash Flow | B21: =B13+B14-B15-B16 -> 15424.45 | C21: =C13+C14-C15-C16 -> 18871.34 | D21: =D13+D14-D15-D16 -> 41104.2 | E21: =E13+E14-E15-E16 -> 34370.16 | F21: =F13+F14-F15-F16 -> 23931.284 | G21: =G13+G14-G15-G16 -> 30166.924 | H21: =H13+H14-H15-H16 -> 31006.938 | I21: =I13+I14-I15-I16 -> 32966.572 | ... M21: =M13+M14-M15-M16 -> 17547.917
A23: Assumptions
A24: =A2 -> Particulars
A25: Revenue Growth | C25: =C3/B3-1 -> 0.060207112 | D25: =D3/C3-1 -> 0.067675447 | E25: =E3/D3-1 -> -0.005740233 | F25: =F3/E3-1 -> -0.022638446 | G25: =AVERAGE(C25:F25) -> 0.02487597 | H25: =AVERAGE(D25:G25) -> 0.016043184 | I25: =AVERAGE(E25:H25) -> 0.0031351187 | J25: =AVERAGE(F25:I25) -> 0.0053539566 | K25: =AVERAGE(G25:J25) -> 0.012352057 | L25: =AVERAGE(H25:K25) -> 0.0092210792 | M25: =AVERAGE(I25:L25) -> 0.0075155529
A27: COGS % of Revenue | B27: =B4/B3 -> 0.090401467 | C27: =C4/C3 -> 0.092540353 | D27: =D4/D3 -> 0.086946212 | E27: =E4/E3 -> 0.091222321 | F27: =F4/F3 -> 0.1041237 | G27: =AVERAGE(B27:F27) -> 0.09304681 | H27: =AVERAGE(C27:G27) -> 0.093575879 | I27: =AVERAGE(D27:H27) -> 0.093782984 | J27: =AVERAGE(E27:I27) -> 0.095150339 | K27: =AVERAGE(F27:J27) -> 0.095935942 | L27: =AVERAGE(G27:K27) -> 0.094298391 | M27: =AVERAGE(H27:L27) -> 0.094548707
A28: SG&A % of Revenue | B28: =B7/B3 -> 0.019942043 | C28: =C7/C3 -> 0.021016748 | D28: =D7/D3 -> 0.020269538 | E28: =E7/E3 -> 0.022295922 | F28: =F7/F3 -> 0.023891489 | G28: =AVERAGE(B28:F28) -> 0.021483148 | H28: =AVERAGE(C28:G28) -> 0.021791369 | I28: =AVERAGE(D28:H28) -> 0.021946293 | J28: =AVERAGE(E28:I28) -> 0.022281644 | K28: =AVERAGE(F28:J28) -> 0.022278789 | L28: =AVERAGE(G28:K28) -> 0.021956249 | M28: =AVERAGE(H28:L28) -> 0.022050869
A29: Tax % of EBIT | B29: =B12/B11 -> 0.14171791 | C29: =C12/C11 -> 0.11865587 | D29: =D12/D11 -> 0.084060471 | E29: =E12/E11 -> 0.10519168 | F29: =F12/F11 -> 0.13736299 | G29: =AVERAGE(B29:F29) -> 0.11739778 | H29: =AVERAGE(C29:G29) -> 0.11253376 | I29: =AVERAGE(D29:H29) -> 0.11130934 | J29: =AVERAGE(E29:I29) -> 0.11675911 | K29: =AVERAGE(F29:J29) -> 0.1190726 | L29: =AVERAGE(G29:K29) -> 0.11541452 | M29: =AVERAGE(H29:L29) -> 0.11501786

Sheet WACC
A1: Weighted Average Cost of Capital (WACC)
A2: Equity (mm) | B2: ='Balance_Sheet(5 years)'!F7 -> 92215.65
A3: Debt (mm) | B3: ='Balance_Sheet(5 years)'!F54 -> 130964.96 | G3: Beta Analysis
G4: SENSEX | H4: 1.02
A5: Cost of Debt | B5: ='Income_Statement(5 years)'!F21/B3 -> 0.072380582 | G5: NIFTY | H5: 1.03
A6: Tax Rate | B6: 0.3
A7: D/(D+E) | B7: =B3/(B3+B2) -> 0.58681155
A8: After Tax Cost of Debt | B8: =B5*(1-B6) -> 0.050666407
A10: Risk Free Rate (10-Yr Treasury Yield) | B10: 0.0697
A11: Expected Market Return | B11: 0.2
A12: Market Risk Premium | B12: =B11-B10 -> 0.1303
A13: Levered Beta | B13: =H4 -> 1.02
A14: E/(D+E) | B14: =B2/(B2+B3) -> 0.41318845
A15: Cost of Equity | B15: =B10+B13*(B12) -> 0.202606
A17: WACC | B17: =(B7*B8)+(B14*B15) -> 0.11344609

Sheet NWC
A1: Net Working Capital | G1: Projections
A2: Fiscal Year | B2: Mar-2021 | C2: Mar-2022 | D2: Mar-2023 | E2: 45352 | F2: Mar-2025 | G2: 46082 | H2: 46447 | I2: 46813 | J2: 47178 | K2: 47543 | L2: 47908 | M2: 48274
A3: Accounts Receivables | B3: ='Balance_Sheet(5 years)'!B42 -> 8470.2 | C3: ='Balance_Sheet(5 years)'!C42 -> 8836.81 | D3: ='Balance_Sheet(5 years)'!D42 -> 14304.13 | E3: ='Balance_Sheet(5 years)'!E42 -> 10825.8 | F3: ='Balance_Sheet(5 years)'!F42 -> 7273.25 | G3: =G17*G14/365 -> 10297.832 | H3: =H17*H14/365 -> 10615.246 | I3: =I17*I14/365 -> 10862.817 | J3: =J17*J14/365 -> 10185.671 | K3: =K17*K14/365 -> 10124.009 | L3: =L17*L14/365 -> 10700.069 | M3: =M17*M14/365 -> 10764.201
A4: Merchandise Inventory | B4: ='Balance_Sheet(5 years)'!B41 -> 1362.82 | C4: ='Balance_Sheet(5 years)'!C41 -> 1352.6 | D4: ='Balance_Sheet(5 years)'!D41 -> 1323.55 | E4: ='Balance_Sheet(5 years)'!E41 -> 1303.73 | F4: ='Balance_Sheet(5 years)'!F41 -> 1377.82 | G4: =G18*G15/365 -> 1406.3995 | H4: =H18*H15/365 -> 1401.3394 | I4: =I18*I15/365 -> 1393.4944 | J4: =J18*J15/365 -> 1410.0282 | K4: =K18*K15/365 -> 1442.1411 | L4: =L18*L15/365 -> 1448.9483 | M4: =M18*M15/365 -> 1454.9795
A5: Other Current Assets | B5: ='Balance_Sheet(5 years)'!B44 -> 935.69 | C5: ='Balance_Sheet(5 years)'!C44 -> 660.41 | D5: ='Balance_Sheet(5 years)'!D44 -> 752.63 | E5: ='Balance_Sheet(5 years)'!E44 -> 413.69 | F5: ='Balance_Sheet(5 years)'!F44 -> 542.41 | G5: =G21*G14 -> 695.38452 | H5: =H21*H14 -> 633.49536 | I5: =I21*I14 -> 619.43116 | J5: =J21*J14 -> 593.68388 | K5: =K21*K14 -> 635.24917 | L5: =L21*L14 -> 652.93238 | M5: =M21*M14 -> 642.71246
A6: Current Assets | B6: =SUM(B3:B5) -> 10768.71 | C6: =SUM(C3:C5) -> 10849.82 | D6: =SUM(D3:D5) -> 16380.31 | E6: =SUM(E3:E5) -> 12543.22 | F6: =SUM(F3:F5) -> 9193.48 | G6: =SUM(G3:G5) -> 12399.616 | H6: =SUM(H3:H5) -> 12650.081 | I6: =SUM(I3:I5) -> 12875.743 | ... M6: =SUM(M3:M5) -> 12861.893
A8: Accounts Payable | B8: ='Balance_Sheet(5 years)'!B17 -> 186.3 | C8: ='Balance_Sheet(5 years)'!C17 -> 266.14 | D8: ='Balance_Sheet(5 years)'!D17 -> 325.02 | E8: ='Balance_Sheet(5 years)'!E17 -> 354.07 | F8: ='Balance_Sheet(5 years)'!F17 -> 567.68 | G8: =G19*G15/365 -> 345.75679 | H8: =H19*H15/365 -> 379.78427 | I8: =I19*I15/365 -> 399.72019 | J8: =J19*J15/365 -> 416.66659 | K8: =K19*K15/365 -> 432.9717 | L8: =L19*L15/365 -> 405.08313 | M8: =M19*M15/365 -> 416.9366
A9: Other Current Liabilities | B9: ='Balance_Sheet(5 years)'!B18 -> 26275.61 | C9: ='Balance_Sheet(5 years)'!C18 -> 25780.92 | D9: ='Balance_Sheet(5 years)'!D18 -> 22532.63 | E9: ='Balance_Sheet(5 years)'!E18 -> 27106.35 | F9: ='Balance_Sheet(5 years)'!F18 -> 26458.69 | G9: =G22*G14 -> 26748.907 | H9: =H22*H14 -> 26594.278 | I9: =I22*I14 -> 26425.066 | J9: =J22*J14 -> 27280.901 | K9: =K22*K14 -> 27508.322 | L9: =L22*L14 -> 27636.6 | M9: =M22*M14 -> 27770.344
A10: Current Liabilities | B10: =SUM(B8:B9) -> 26461.91 | C10: =SUM(C8:C9) -> 26047.06 | D10: =SUM(D8:D9) -> 22857.65 | E10: =SUM(E8:E9) -> 27460.42 | F10: =SUM(F8:F9) -> 27026.37 | G10: =SUM(G8:G9) -> 27094.663 | H10: =SUM(H8:H9) -> 26974.063 | I10: =SUM(I8:I9) -> 26824.786 | ... M10: =SUM(M8:M9) -> 28187.281
A12: Assumptions
A13: Fiscal Year | B13: Mar-2021 | C13: Mar-2022 | D13: Mar-2023 | E13: 45352 | F13: Mar-2025 | G13: 46082 | H13: 46447 | I13: 46813 | J13: 47178 | K13: 47543 | L13: 47908 | M13: 48274
A14: Revenue | B14: =FCFF_Projections!B3 -> 37665.65 | C14: =FCFF_Projections!C3 -> 39933.39 | D14: =FCFF_Projections!D3 -> 42635.9 | E14: =FCFF_Projections!E3 -> 42391.16 | F14: =FCFF_Projections!F3 -> 41431.49 | G14: =FCFF_Projections!G3 -> 42462.138 | H14: =FCFF_Projections!H3 -> 43143.366 | I14: =FCFF_Projections!I3 -> 43278.626 | ... M14: =FCFF_Projections!M3 -> 44788.044
A15: COGS | B15: =FCFF_Projections!B4 -> 3405.03 | C15: =FCFF_Projections!C4 -> 3695.45 | D15: =FCFF_Projections!D4 -> 3707.03 | E15: =FCFF_Projections!E4 -> 3867.02 | F15: =FCFF_Projections!F4 -> 4314 | G15: =FCFF_Projections!G4 -> 3950.9665 | H15: =FCFF_Projections!H4 -> 4037.1784 | I15: =FCFF_Projections!I4 -> 4058.7987 | ... M15: =FCFF_Projections!M4 -> 4234.6517
A17: Days Sales Outstanding (DSO) | B17: =(B3/B14)*365 -> 82.080702 | C17: =(C3/C14)*365 -> 80.770394 | D17: =(D3/D14)*365 -> 122.45566 | E17: =(E3/E14)*365 -> 93.213231 | F17: =(F3/F14)*365 -> 64.075327 | G17: =AVERAGE(B17:F17) -> 88.519064 | H17: =AVERAGE(C17:G17) -> 89.806736 | I17: =AVERAGE(D17:H17) -> 91.614004 | J17: =AVERAGE(E17:I17) -> 85.445672 | K17: =AVERAGE(F17:J17) -> 83.892161 | L17: =AVERAGE(G17:K17) -> 87.855527 | M17: =AVERAGE(H17:L17) -> 87.72282
A18: Days Inventory Outstanding (DIO) | B18: =B4/B15*365 -> 146.08661 | C18: =C4/C15*365 -> 133.59645 | D18: =D4/D15*365 -> 130.31881 | E18: =E4/E15*365 -> 123.05637 | F18: =F4/F15*365 -> 116.57494 | G18: =AVERAGE(B18:F18) -> 129.92664 | H18: =AVERAGE(C18:G18) -> 126.69464 | I18: =AVERAGE(D18:H18) -> 125.31428 | J18: =AVERAGE(E18:I18) -> 124.31338 | K18: =AVERAGE(F18:J18) -> 124.56478 | L18: =AVERAGE(G18:K18) -> 126.16274 | M18: =AVERAGE(H18:L18) -> 125.40996
A19: Days Payable Outstanding (DPO) | B19: =B8/B15*365 -> 19.970309 | C19: =C8/C15*365 -> 26.286677 | D19: =D8/D15*365 -> 32.00198 | E19: =E8/E15*365 -> 33.419933 | F19: =F8/F15*365 -> 48.030413 | G19: =AVERAGE(B19:F19) -> 31.941862 | H19: =AVERAGE(C19:G19) -> 34.336173 | I19: =AVERAGE(D19:H19) -> 35.946072 | J19: =AVERAGE(E19:I19) -> 36.734891 | K19: =AVERAGE(F19:J19) -> 37.397882 | L19: =AVERAGE(G19:K19) -> 35.271376 | M19: =AVERAGE(H19:L19) -> 35.937279
A21: Other Current Assets as a % of Revenue | B21: =B5/B14 -> 0.024841998 | C21: =C5/C14 -> 0.01653779 | D21: =D5/D14 -> 0.017652495 | E21: =E5/E14 -> 0.0097588743 | F21: =F5/F14 -> 0.013091733 | G21: =AVERAGE(B21:F21) -> 0.016376578 | H21: =AVERAGE(C21:G21) -> 0.014683494 | I21: =AVERAGE(D21:H21) -> 0.014312635 | J21: =AVERAGE(E21:I21) -> 0.013644663 | K21: =AVERAGE(F21:J21) -> 0.01442182 | L21: =AVERAGE(G21:K21) -> 0.014687838 | M21: =AVERAGE(H21:L21) -> 0.01435009
A22: Other Current Liabilities as a % of Revenue | B22: =B9/B14 -> 0.6976014 | C22: =C9/C14 -> 0.64559808 | D22: =D9/D14 -> 0.52848961 | E22: =E9/E14 -> 0.63943402 | F22: =F9/F14 -> 0.63861305 | G22: =AVERAGE(B22:F22) -> 0.62994723 | H22: =AVERAGE(C22:G22) -> 0.6164164 | I22: =AVERAGE(D22:H22) -> 0.61058006 | J22: =AVERAGE(E22:I22) -> 0.62699815 | K22: =AVERAGE(F22:J22) -> 0.62451098 | L22: =AVERAGE(G22:K22) -> 0.62169056 | M22: =AVERAGE(H22:L22) -> 0.62003923

Sheet Fixed_Assets
A1: Fixed Assets Schedule | G1: Projections
A2: Fiscal Year | B2: Mar-2021 | C2: Mar-2022 | D2: Mar-2023 | E2: 45352 | F2: Mar-2025 | G2: 46082 | H2: 46447 | I2: 46813 | J2: 47178 | K2: 47543 | L2: 47908 | M2: 48274
A3: Beginning PP&E | B3: ='Balance_Sheet(5 years)'!B29 -> 176943.5 | C3: ='Balance_Sheet(5 years)'!C29 -> 179731.76 | D3: ='Balance_Sheet(5 years)'!D29 -> 172277.55 | E3: ='Balance_Sheet(5 years)'!E29 -> 162700.51 | F3: ='Balance_Sheet(5 years)'!F29 -> 153634.86 | G3: =F3-F4+F5 -> 147075.27 | H3: =G3-G4+G5 -> 140161.96 | I3: =H3-H4+H5 -> 133304.51 | J3: =I3-I4+I5 -> 126879.83 | K3: =J3-J4+J5 -> 120932.58 | L3: =K3-K4+K5 -> 115036.59 | M3: =L3-L4+L5 -> 109548.79
A4: D&A | B4: ='Income_Statement(5 years)'!B23 -> 11711.68 | C4: ='Income_Statement(5 years)'!C23 -> 12550.58 | D4: ='Income_Statement(5 years)'!D23 -> 12858.52 | E4: ='Income_Statement(5 years)'!E23 -> 12558.19 | F4: ='Income_Statement(5 years)'!F23 -> 12352.23 | G4: =G10*G3 -> 10831.875 | H4: =H10*H3 -> 10531.833 | I4: =I10*I3 -> 10158.156 | J4: =J10*J3 -> 9708.2725 | K4: =K10*K3 -> 9237.0002 | L4: =L10*L3 -> 8694.2006 | M4: =M10*M3 -> 8321.7139
A5: CapEx | B5: =B6-B3+B4 -> 14499.94 | C5: =C6-C3+C4 -> 5096.37 | D5: =D6-D3+D4 -> 3281.48 | E5: =E6-E3+E4 -> 3492.54 | F5: =F11*F3 -> 5792.6429 | G5: =G11*G3 -> 3918.5665 | H5: =H11*H3 -> 3674.3787 | I5: =I11*I3 -> 3733.4772 | J5: =J11*J3 -> 3761.0228 | K5: =K11*K3 -> 3341.0056 | L5: =L11*L3 -> 3206.4084 | M5: =M11*M3 -> 3098.8475
A6: Ending PP&E | B6: ='Balance_Sheet(5 years)'!C29 -> 179731.76 | C6: ='Balance_Sheet(5 years)'!D29 -> 172277.55 | D6: ='Balance_Sheet(5 years)'!E29 -> 162700.51 | E6: ='Balance_Sheet(5 years)'!F29 -> 153634.86 | F6: =F3-F4+F5 -> 147075.27 | G6: =G3-G4+G5 -> 140161.96 | H6: =H3-H4+H5 -> 133304.51 | I6: =I3-I4+I5 -> 126879.83 | J6: =J3-J4+J5 -> 120932.58 | K6: =K3-K4+K5 -> 115036.59 | L6: =L3-L4+L5 -> 109548.79 | M6: =M3-M4+M5 -> 104325.93
A8: Assumptions
A9: Fiscal Year | B9: Mar-2021 | C9: Mar-2022 | D9: Mar-2023 | E9: 45352 | F9: Mar-2025 | G9: 46082 | H9: 46447 | I9: 46813 | J9: 47178 | K9: 47543 | L9: 47908 | M9: 48274
A10: D&A as a % of Beginning PP&E | B10: =B4/B3 -> 0.066188812 | C10: =C4/C3 -> 0.069829506 | D10: =D4/D3 -> 0.074638396 | E10: =E4/E3 -> 0.077185929 | F10: =F4/F3 -> 0.080399917 | G10: =AVERAGE(B10:F10) -> 0.073648512 | H10: =AVERAGE(C10:G10) -> 0.075140452 | I10: =AVERAGE(D10:H10) -> 0.076202641 | J10: =AVERAGE(E10:I10) -> 0.07651549 | K10: =AVERAGE(F10:J10) -> 0.076381402 | L10: =AVERAGE(G10:K10) -> 0.0755777 | M10: =AVERAGE(H10:L10) -> 0.075963537
A11: CapEx as a % of Beginning PP&E | B11: =B5/B3 -> 0.081946723 | C11: =C5/C3 -> 0.028355423 | D11: =D5/D3 -> 0.019047636 | E11: =E5/E3 -> 0.021466067 | F11: =AVERAGE(B11:E11) -> 0.037703962 | G11: =AVERAGE(C11:F11) -> 0.026643272 | H11: =AVERAGE(D11:G11) -> 0.026215234 | I11: =AVERAGE(E11:H11) -> 0.028007134 | J11: =AVERAGE(F11:I11) -> 0.0296424 | K11: =AVERAGE(G11:J11) -> 0.02762701 | L11: =AVERAGE(H11:K11) -> 0.027872944 | M11: =AVERAGE(I11:L11) -> 0.028287372

Sheet Peer_Group_FA(5 years)
B3: Adani Transmission | C3: 43891 | D3: 44256 | E3: 44621 | F3: 44986 | G3: 45352 | K3: TATA Power | L3: 43891 | M3: 44256 | N3: 44621 | O3: 44986 | P3: 45352 | S3: NHPC | T3: 43891 | U3: 44256 | V3: 44621 | W3: 44986 | X3: 45352 | AA3: Power Grid Corporation | AB3: 43891 | AC3: 44256 | AD3: 44621 | AE3: 44986 | AF3: 45352
B4: Shareholder's Equity | C4: 2110.47 | D4: 2230.57 | E4: 2506.44 | F4: 2824.06 | G4: 3124.41 | K4: Shareholder's Equity | L4: 13761.97 | M4: 8378.07 | N4: 10879.8 | O4: 13699.59 | P4: 15787.66 | S4: Shareholder's Equity | T4: 29983.81 | U4: 31603.11 | V4: 33486.1 | W4: 35407.96 | X4: 37275.95 | AA4: Shareholder's Equity | AB4: 64439.69 | AC4: ='Balance_Sheet(5 years)'!B7 -> 69578.84 | AD4: ='Balance_Sheet(5 years)'!C7 -> 76151.57 | AE4: ='Balance_Sheet(5 years)'!D7 -> 82844.18 | AF4: ='Balance_Sheet(5 years)'!E7 -> 86867.05
B5: Total Debt | C5: 1508.58 | D5: 1205.54 | E5: 553.68 | F5: 516.18 | G5: 470.37 | K5: Total Debt | L5: 19301.66 | M5: 25961.3 | N5: 24708.38 | O5: 21865.48 | P5: 19526.16 | S5: Total Debt | T5: 23223.83 | U5: 23352.55 | V5: 26017.64 | W5: 28140.34 | X5: 30975.99 | AA5: Total Debt | AB5: 147979.64 | AC5: ='Balance_Sheet(5 years)'!B54 -> 143051.48 | AD5: ='Balance_Sheet(5 years)'!C54 -> 134665.27 | AE5: ='Balance_Sheet(5 years)'!D54 -> 128517.51 | AF5: ='Balance_Sheet(5 years)'!E54 -> 123448.62
B6: Cash & Cash Equivalents | C6: 3.57 | D6: 0.42 | E6: 1.58 | F6: 7.15 | G6: 1.52 | K6: Cash & Cash Equivalents | L6: 178.94 | M6: 383.13 | N6: 78.55 | O6: 295.92 | P6: 618.59 | S6: Cash & Cash Equivalents | T6: 389.12 | U6: 913.96 | V6: 1160.71 | W6: 638.22 | X6: 1150.36 | AA6: Cash & Cash Equivalents | AB6: 5409.4 | AC6: ='Balance_Sheet(5 years)'!B43 -> 5273.54 | AD6: ='Balance_Sheet(5 years)'!C43 -> 2971.04 | AE6: ='Balance_Sheet(5 years)'!D43 -> 4734.44 | AF6: ='Balance_Sheet(5 years)'!E43 -> 5026.73
B7: Book value/share | C7: 175.8 | D7: 202.69 | E7: 227.75 | F7: 256.62 | G7: 174.87 | K7: Book value/share | L7: 50.89 | M7: 26.22 | N7: 34.05 | O7: 42.88 | P7: 49.39 | S7: Book value/share | T7: 29.85 | U7: 31.46 | V7: 33.34 | W7: 35.25 | X7: 37.11 | AA7: Book value/share | AB7: 69.29 | AC7: ='Balance_Sheet(5 years)'!B56 -> 74.81 | AD7: ='Balance_Sheet(5 years)'!C56 -> 81.88 | AE7: ='Balance_Sheet(5 years)'!D56 -> 89.07 | AF7: ='Balance_Sheet(5 years)'!E56 -> 93.4
B8: Revenue | C8: 976.01 | D8: 868.49 | E8: 769.64 | F8: 784.7 | G8: 717.69 | K8: Revenue | L8: 7726.39 | M8: 13169.48 | N8: 11107.93 | O8: 17727.78 | P8: 20093.36 | S8: Revenue | T8: 8735.15 | U8: 8506.58 | V8: 8309.22 | W8: 9316.34 | X8: 8396.49 | AA8: Revenue | AB8: 36185.54 | AC8: ='Income_Statement(5 years)'!B7 -> 37665.65 | AD8: ='Income_Statement(5 years)'!C7 -> 39933.39 | AE8: ='Income_Statement(5 years)'!D7 -> 42635.9 | AF8: ='Income_Statement(5 years)'!E7 -> 42391.16
B9: EBITDA | C9: 877.17 | D9: 802.01 | E9: 729.96 | F9: 719.9 | G9: 690.31 | K9: EBITDA | L9: 3504.41 | M9: 3982.16 | N9: 4534.51 | O9: 5696.77 | P9: 5753.02 | S9: EBITDA | T9: 5685.98 | U9: 5786.1 | V9: 5738.75 | W9: 6253.9 | X9: 5877.12 | AA9: EBITDA | AB9: 33534.15 | AC9: ='Income_Statement(5 years)'!B20 -> 36140.5 | AD9: ='Income_Statement(5 years)'!C20 -> 37329.49 | AE9: ='Income_Statement(5 years)'!D20 -> 39552.67 | AF9: ='Income_Statement(5 years)'!E20 -> 40179.03
B10: EBIT | C10: 620.89 | D10: 545.33 | E10: 472.75 | F10: 458.36 | G10: 427.8 | K10: EBIT | L10: 2818.66 | M10: 2747.46 | N10: 3400.28 | O10: 4529.3 | P10: 4564.56 | S10: EBIT | T10: 4140.64 | U10: 4557.45 | V10: 4612.53 | W10: 5108.46 | X10: 4766.12 | AA10: EBIT | AB10: 22460.97 | AC10: 24428.82 | AD10: 24778.91 | AE10: 26694.15 | AF10: 27620.84
B11: Net Profit | C11: 267.91 | D11: 295.85 | E11: 305.1 | F11: 313.57 | G11: 304.54 | K11: Net Profit | L11: 558.35 | M11: 339.71 | N11: 3250.76 | O11: 3267.9 | P11: 2229.86 | S11: Net Profit | T11: 3007.17 | U11: 3245.06 | V11: 3537.71 | W11: 3833.79 | X11: 3721.8 | AA11: Net Profit | AB11: 10811.18 | AC11: 11935.78 | AD11: 17093.76 | AE11: 15124.54 | AF11: 15377.48
B12: EPS | C12: 28.41 | D12: 26.88 | E12: 25.07 | F12: 28.86 | G12: 27.3 | K12: EPS | L12: 2.06 | M12: 1.06 | N12: 10.17 | O12: 10.23 | P12: 6.98 | S12: EPS | T12: 2.99 | U12: 3.23 | V12: 3.52 | W12: 3.82 | X12: 3.71 | AA12: EPS | AB12: 11.62 | AC12: 12.83 | AD12: 18.38 | AE12: 16.26 | AF12: 16.53
B13: Market Data | K13: Market Data | S13: Market Data | AA13: Market Data
B14: Shares Outstanding | C14: 128 | D14: 109 | E14: 109 | F14: 111 | G14: 111 | K14: Shares Outstanding | L14: 381 | M14: 320 | N14: 320 | O14: 319 | P14: 320 | S14: Shares Outstanding | T14: 999 | U14: 1003 | V14: 1002 | W14: 1014 | X14: 1005 | AA14: Shares Outstanding | AB14: 930 | AC14: 930 | AD14: 930 | AE14: 930 | AF14: 930
B15: Face Value | C15: 10 | D15: 10 | E15: 10 | F15: 10 | G15: 10 | K15: Face Value | L15: 1 | M15: 1 | N15: 1 | O15: 1 | P15: 1 | S15: Face Value | T15: 10 | U15: 10 | V15: 10 | W15: 10 | X15: 10 | AA15: Face Value | AB15: 10 | AC15: 10 | AD15: 10 | AE15: 10 | AF15: 10
B16: Current Share Price | C16: 427 | D16: 1949 | E16: 2658 | F16: 895 | G16: 771 | K16: Current Share Price | L16: 72.68 | M16: 214.91 | N16: 203.64 | O16: 328.68 | P16: 390.1 | S16: Current Share Price | T16: 22.65 | U16: 30.95 | V16: 39.75 | W16: 64.6 | X16: 80.69 | AA16: Current Share Price | AB16: 103.25 | AC16: 153.3 | AD16: 156.7 | AE16: 237.2 | AF16: 308.6
B17: Market Cap | C17: 54600 | D17: 212500 | E17: 289700 | F17: 99300 | G17: 92600 | K17: Market Cap | L17: 275000 | M17: 789000 | N17: 667000 | O17: 1062000 | P17: 1242000 | S17: Market Cap | T17: 25900 | U17: 34600 | V17: 40000 | W17: 64700 | X17: 78500 | AA17: Market Cap | AB17: 96000 | AC17: 142600 | AD17: 145700 | AE17: 220600 | AF17: 286100
B18: Valuation Metrics | K18: Valuation Metrics | S18: Valuation Metrics | AA18: Valuation Metrics
B19: EV | C19: =C17+C5-C6 -> 56105.01 | D19: =D17+D5-D6 -> 213705.12 | E19: =E17+E5-E6 -> 290252.1 | F19: =F17+F5-F6 -> 99809.03 | G19: =G17+G5-G6 -> 93068.85 | K19: EV | L19: =L17+L5-L6 -> 294122.72 | M19: =M17+M5-M6 -> 814578.17 | N19: =N17+N5-N6 -> 691629.83 | O19: =O17+O5-O6 -> 1083569.6 | P19: =P17+P5-P6 -> 1260907.6 | S19: EV | T19: =T17+T5-T6 -> 48734.71 | U19: =U17+U5-U6 -> 57038.59 | V19: =V17+V5-V6 -> 64856.93 | W19: =W17+W5-W6 -> 92202.12 | X19: =X17+X5-X6 -> 108325.63 | AA19: EV | AB19: =AB17+AB5-AB6 -> 238570.24 | AC19: =AC17+AC5-AC6 -> 280377.94 | AD19: =AD17+AD5-AD6 -> 277394.23 | AE19: =AE17+AE5-AE6 -> 344383.07 | AF19: =AF17+AF5-AF6 -> 404521.89
B20: P/E | C20: =C16/C12 -> 15.029919 | D20: =D16/D12 -> 72.50744 | E20: =E16/E12 -> 106.02314 | F20: =F16/F12 -> 31.011781 | G20: =G16/G12 -> 28.241758 | K20: P/E | L20: =L16/L12 -> 35.281553 | M20: =M16/M12 -> 202.74528 | N20: =N16/N12 -> 20.023599 | O20: =O16/O12 -> 32.129032 | P20: =P16/P12 -> 55.888252 | S20: P/E | T20: =T16/T12 -> 7.5752508 | U20: =U16/U12 -> 9.5820433 | V20: =V16/V12 -> 11.292614 | W20: =W16/W12 -> 16.910995 | X20: =X16/X12 -> 21.749326 | AA20: P/E | AB20: =AB16/AB12 -> 8.8855422 | AC20: =AC16/AC12 -> 11.948558 | AD20: =AD16/AD12 -> 8.5255713 | AE20: =AE16/AE12 -> 14.587946 | AF20: =AF16/AF12 -> 18.669087
B21: P/V | C21: =C16/C7 -> 2.4288965 | D21: =D16/D7 -> 9.6156692 | E21: =E16/E7 -> 11.670692 | F21: =F16/F7 -> 3.4876471 | G21: =G16/G7 -> 4.4089895 | K21: P/V | L21: =L16/L7 -> 1.4281784 | M21: =M16/M7 -> 8.196415 | N21: =N16/N7 -> 5.9806167 | O21: =O16/O7 -> 7.6651119 | P21: =P16/P7 -> 7.89836 | S21: P/V | T21: =T16/T7 -> 0.75879397 | U21: =U16/U7 -> 0.98378894 | V21: =V16/V7 -> 1.1922615 | W21: =W16/W7 -> 1.8326241 | X21: =X16/X7 -> 2.1743465 | AA21: P/V | AB21: =AB16/AB7 -> 1.490114 | AC21: =AC16/AC7 -> 2.0491913 | AD21: =AD16/AD7 -> 1.9137763 | AE21: =AE16/AE7 -> 2.663074 | AF21: =AF16/AF7 -> 3.3040685
B22: EV/EBITDA | C22: =C19/C9 -> 63.961387 | D22: =D19/D9 -> 266.46191 | E22: =E19/E9 -> 397.6274 | F22: =F19/F9 -> 138.64291 | G22: =G19/G9 -> 134.82182 | K22: EV/EBITDA | L22: =L19/L9 -> 83.929312 | M22: =M19/M9 -> 204.55687 | N22: =N19/N9 -> 152.52581 | O22: =O19/O9 -> 190.20771 | P22: =P19/P9 -> 219.17316 | S22: EV/EBITDA | T22: =T19/T9 -> 8.5710309 | U22: =U19/U9 -> 9.8578645 | V22: =V19/V9 -> 11.301578 | W22: =W19/W9 -> 14.743139 | X22: =X19/X9 -> 18.431754 | AA22: EV/EBITDA | AB22: =AB19/AB9 -> 7.1142474 | AC22: =AC19/AC9 -> 7.7579984 | AD22: =AD19/AD9 -> 7.4309676 | AE22: =AE19/AE9 -> 8.7069487 | AF22: =AF19/AF9 -> 10.067985
B23: EV/EBIT | C23: =C19/C10 -> 90.362238 | D23: =D19/D10 -> 391.8822 | E23: =E19/E10 -> 613.96531 | F23: =F19/F10 -> 217.75249 | G23: =G19/G10 -> 217.55224 | K23: EV/EBIT | L23: =L19/L10 -> 104.34842 | M23: =M19/M10 -> 296.48409 | N23: =N19/N10 -> 203.40379 | O23: =O19/O10 -> 239.23555 | P23: =P19/P10 -> 276.23858 | S23: EV/EBIT | T23: =T19/T10 -> 11.76985 | U23: =U19/U10 -> 12.515461 | V23: =V19/V10 -> 14.061032 | W23: =W19/W10 -> 18.048907 | X23: =X19/X10 -> 22.728263 | AA23: EV/EBIT | AB23: =AB19/AB10 -> 10.621547 | AC23: =AC19/AC10 -> 11.477343 | AD23: =AD19/AD10 -> 11.194771 | AE23: =AE19/AE10 -> 12.901069 | AF23: =AF19/AF10 -> 14.645532
B24: EV/Sales | C24: =C19/C8 -> 57.484052 | D24: =D19/D8 -> 246.06515 | E24: =E19/E8 -> 377.1271 | F24: =F19/F8 -> 127.19387 | G24: =G19/G8 -> 129.67834 | K24: EV/Sales | L24: =L19/L8 -> 38.067289 | M24: =M19/M8 -> 61.85348 | N24: =N19/N8 -> 62.264511 | O24: =O19/O8 -> 61.122688 | P24: =P19/P8 -> 62.75245 | S24: EV/Sales | T24: =T19/T8 -> 5.5791498 | U24: =U19/U8 -> 6.7052317 | V24: =V19/V8 -> 7.8054174 | W24: =W19/W8 -> 9.8968178 | X24: =X19/X8 -> 12.901299 | AA24: EV/Sales | AB24: =AB19/AB8 -> 6.5929717 | AC24: =AC19/AC8 -> 7.443863 | AD24: =AD19/AD8 -> 6.9464233 | AE24: =AE19/AE8 -> 8.0773027 | AF24: =AF19/AF8 -> 9.5426002

Sheet Relative_Valuation
B5: Multiple | C5: Adani Transmission | D5: TATA Power | E5: NHPC | F5: Power Grid | G5: Peer Median Multiple (x)
B6: P/E | C6: ='Peer_Group_FA(5 years)'!G20 -> 28.241758 | D6: ='Peer_Group_FA(5 years)'!P20 -> 55.888252 | E6: ='Peer_Group_FA(5 years)'!X20 -> 21.749326 | F6: ='Peer_Group_FA(5 years)'!AF20 -> 18.669087 | G6: 15
B7: P/V | C7: ='Peer_Group_FA(5 years)'!G21 -> 4.4089895 | D7: ='Peer_Group_FA(5 years)'!P21 -> 7.89836 | E7: ='Peer_Group_FA(5 years)'!X21 -> 2.1743465 | F7: ='Peer_Group_FA(5 years)'!AF21 -> 3.3040685 | G7: 2.5
B8: EV/EBITDA | C8: ='Peer_Group_FA(5 years)'!G22 -> 134.82182 | D8: ='Peer_Group_FA(5 years)'!P22 -> 219.17316 | E8: ='Peer_Group_FA(5 years)'!X22 -> 18.431754 | F8: ='Peer_Group_FA(5 years)'!AF22 -> 10.067985 | G8: 9
B9: EV/EBIT | C9: ='Peer_Group_FA(5 years)'!G23 -> 217.55224 | D9: ='Peer_Group_FA(5 years)'!P23 -> 276.23858 | E9: ='Peer_Group_FA(5 years)'!X23 -> 22.728263 | F9: ='Peer_Group_FA(5 years)'!AF23 -> 14.645532 | G9: 11
B10: EV/Sales | C10: ='Peer_Group_FA(5 years)'!G24 -> 129.67834 | D10: ='Peer_Group_FA(5 years)'!P24 -> 62.75245 | E10: ='Peer_Group_FA(5 years)'!X24 -> 12.901299 | F10: ='Peer_Group_FA(5 years)'!AF24 -> 9.5426002 | G10: 3
B13: Implied Share Prices (Power Grid Oil Corporation of India) | D13: Weights
B14: P/E | C14: =F6*G6 -> 280.0363 | D14: 0.47 | E14: =C14*D14 -> 131.61706
B15: P/V | C15: =G7*'Peer_Group_FA(5 years)'!AF7 -> 233.5 | D15: 0.13 | E15: =C15*D15 -> 30.355
B16: EV/EBITDA | C16: =((G8*'Peer_Group_FA(5 years)'!AF9)-('Peer_Group_FA(5 years)'!AF5-'Peer_Group_FA(5 years)'!AF6))/'Peer_Group_FA(5 years)'!AF14 -> 261.49396 | D16: 0.3 | E16: =C16*D16 -> 78.448187
B17: EV/EBIT | C17: =((G9*'Peer_Group_FA(5 years)'!AF10)-('Peer_Group_FA(5 years)'!AF5-'Peer_Group_FA(5 years)'!AF6))/'Peer_Group_FA(5 years)'!AF14 -> 199.36274 | D17: 0.05 | E17: =C17*D17 -> 9.9681371
B18: EV/Sales | C18: =((G10*'Peer_Group_FA(5 years)'!AF8)-('Peer_Group_FA(5 years)'!AF5-'Peer_Group_FA(5 years)'!AF6))/'Peer_Group_FA(5 years)'!AF14 -> 9.4103118 | D18: 0.05 | E18: =C18*D18 -> 0.47051559
C20: Fair Target Value | E20: =SUM(E14:E18) -> 250.8589

Sheet Technical_Analysis(with Charts)
A1: For Past 5 days | P1: For Past 6 M | AF1: For Past 1 year
A2: Power Grid Corporation Of India Ltd. - Technical Analysis - MACD-2024-09-07-2025-09-07-BSE - [INR-Millions] | P2: Power Grid Corporation Of India Ltd. - Technical Analysis - MACD-2024-09-07-2025-09-07-BSE - [INR-Millions] | AF2: Power Grid Corporation Of India Ltd. - Technical Analysis - MACD-2024-09-07-2025-09-07-BSE - [INR-Millions]
A3: Date | B3: Price | C3: Upper EDMA | D3: Lower EDMA | E3: MACD | F3: MACD of Trigger | G3: CROSSOVERS | P3: Date | Q3: Price | R3: Upper EDMA | S3: Lower EDMA | T3: MACD | U3: MACD of Trigger | V3: CROSSOVERS | AF3: Date | AG3: Price | AH3: Upper EDMA | AI3: Lower EDMA | AJ3: MACD | AK3: MACD of Trigger | AL3: CROSSOVERS
A4: 45905 | B4: 285.4 | C4: 285.57 | D4: 283.46 | E4: -2.11 | F4: -1.76 | G4: SELL | P4: 45905 | Q4: 285.4 | R4: 285.57 | S4: 283.46 | T4: -2.11 | U4: -1.76 | V4: SELL | AF4: 45905 | AG4: 285.4 | AH4: 285.57 | AI4: 283.46 | AJ4: -2.11 | AK4: -1.76 | AL4: SELL
A5: 45904 | B5: 282 | C5: 285.58 | D5: 283.11 | E5: -2.47 | F5: -1.74 | G5: SELL | P5: 45904 | Q5: 282 | R5: 285.58 | S5: 283.11 | T5: -2.47 | U5: -1.74 | V5: SELL | AF5: 45904 | AG5: 282 | AH5: 285.58 | AI5: 283.11 | AJ5: -2.47 | AK5: -1.74 | AL5: SELL
A6: 45903 | B6: 286 | C6: 285.87 | D6: 283.31 | E6: -2.56 | F6: -1.7 | G6: SELL | P6: 45903 | Q6: 286 | R6: 285.87 | S6: 283.31 | T6: -2.56 | U6: -1.7 | V6: SELL | AF6: 45903 | AG6: 286 | AH6: 285.87 | AI6: 283.31 | AJ6: -2.56 | AK6: -1.7 | AL6: SELL
A7: 45902 | B7: 286.65 | C7: 285.86 | D7: 282.82 | E7: -3.04 | F7: -1.65 | G7: SELL | P7: 45902 | Q7: 286.65 | R7: 285.86 | S7: 282.82 | T7: -3.04 | U7: -1.65 | V7: SELL | AF7: 45902 | AG7: 286.65 | AH7: 285.86 | AI7: 282.82 | AJ7: -3.04 | AK7: -1.65 | AL7: SELL
A8: 45901 | B8: 279.85 | C8: 285.79 | D8: 282.12 | E8: -3.67 | F8: -1.58 | G8: SELL | P8: 45901 | Q8: 279.85 | R8: 285.79 | S8: 282.12 | T8: -3.67 | U8: -1.58 | V8: SELL | AF8: 45901 | AG8: 279.85 | AH8: 285.79 | AI8: 282.12 | AJ8: -3.67 | AK8: -1.58 | AL8: SELL
A9: 45898 | B9: 275.35 | C9: 286.27 | D9: 282.53 | E9: -3.73 | F9: -1.46 | G9: SELL | P9: 45898 | Q9: 275.35 | R9: 286.27 | S9: 282.53 | T9: -3.73 | U9: -1.46 | V9: SELL | AF9: 45898 | AG9: 275.35 | AH9: 286.27 | AI9: 282.53 | AJ9: -3.73 | AK9: -1.46 | AL9: SELL
A10: 45897 | B10: 274.5 | C10: 287.14 | D10: 283.84 | E10: -3.3 | F10: -1.34 | G10: SELL | P10: 45897 | Q10: 274.5 | R10: 287.14 | S10: 283.84 | T10: -3.3 | U10: -1.34 | V10: SELL | AF10: 45897 | AG10: 274.5 | AH10: 287.14 | AI10: 283.84 | AJ10: -3.3 | AK10: -1.34 | AL10: SELL
A11: 45895 | B11: 279.8 | C11: 288.15 | D11: 285.54 | E11: -2.61 | F11: -1.23 | G11: SELL | P11: 45895 | Q11: 279.8 | R11: 288.15 | S11: 285.54 | T11: -2.61 | U11: -1.23 | V11: SELL | AF11: 45895 | AG11: 279.8 | AH11: 288.15 | AI11: 285.54 | AJ11: -2.61 | AK11: -1.23 | AL11: SELL
A12: 45894 | B12: 284.15 | C12: 288.82 | D12: 286.58 | E12: -2.24 | F12: -1.16 | G12: SELL | P12: 45894 | Q12: 284.15 | R12: 288.82 | S12: 286.58 | T12: -2.24 | U12: -1.16 | V12: SELL | AF12: 45894 | AG12: 284.15 | AH12: 288.82 | AI12: 286.58 | AJ12: -2.24 | AK12: -1.16 | AL12: SELL
A13: 45891 | B13: 283.35 | C13: 289.19 | D13: 287.02 | E13: -2.17 | F13: -1.1 | G13: SELL | P13: 45891 | Q13: 283.35 | R13: 289.19 | S13: 287.02 | T13: -2.17 | U13: -1.1 | V13: SELL | AF13: 45891 | AG13: 283.35 | AH13: 289.19 | AI13: 287.02 | AJ13: -2.17 | AK13: -1.1 | AL13: SELL
A14: 45890 | B14: 284 | C14: 289.66 | D14: 287.69 | E14: -1.97 | F14: -1.04 | G14: SELL | P14: 45890 | Q14: 284 | R14: 289.66 | S14: 287.69 | T14: -1.97 | U14: -1.04 | V14: SELL | AF14: 45890 | AG14: 284 | AH14: 289.66 | AI14: 287.69 | AJ14: -1.97 | AK14: -1.04 | AL14: SELL
A15: 45889 | B15: 288.35 | C15: 290.12 | D15: 288.36 | E15: -1.75 | F15: -0.99 | G15: SELL | P15: 45889 | Q15: 288.35 | R15: 290.12 | S15: 288.36 | T15: -1.75 | U15: -0.99 | V15: SELL | AF15: 45889 | AG15: 288.35 | AH15: 290.12 | AI15: 288.36 | AJ15: -1.75 | AK15: -0.99 | AL15: SELL
... A212: 45600 | B212: 315.5 | C212: 327.37 | D212: 321.57 | E212: -5.81 | F212: -2.13 | G212: SELL | P212: 45600 | Q212: 315.5 | R212: 327.37 | S212: 321.57 | T212: -5.81 | U212: -2.13 | V212: SELL | AF212: 45600 | AG212: 315.5 | AH212: 327.37 | AI212: 321.57 | AJ212: -5.81 | AK212: -2.13 | AL212: SELL
A213: 45597 | B213: 321.9 | C213: 328.32 | D213: 322.67 | E213: -5.66 | F213: -1.93 | P213: 45597 | Q213: 321.9 | R213: 328.32 | S213: 322.67 | T213: -5.66 | U213: -1.93 | AF213: 45597 | AG213: 321.9 | AH213: 328.32 | AI213: 322.67 | AJ213: -5.66 | AK213: -1.93
A214: 45596 | B214: 321.2 | C214: 328.84 | D214: 322.81 | E214: -6.03 | F214: -1.73 | P214: 45596 | Q214: 321.2 | R214: 328.84 | S214: 322.81 | T214: -6.03 | U214: -1.73 | AF214: 45596 | AG214: 321.2 | AH214: 328.84 | AI214: 322.81 | AJ214: -6.03 | AK214: -1.73
A215: 45595 | B215: 318.45 | C215: 329.45 | D215: 323.1 | E215: -6.35 | F215: 0 | P215: 45595 | Q215: 318.45 | R215: 329.45 | S215: 323.1 | T215: -6.35 | U215: 0 | AF215: 45595 | AG215: 318.45 | AH215: 329.45 | AI215: 323.1 | AJ215: -6.35 | AK215: 0
A216: 45594 | B216: 320.65 | C216: 330.33 | D216: 323.95 | E216: -6.38 | F216: 0 | P216: 45594 | Q216: 320.65 | R216: 330.33 | S216: 323.95 | T216: -6.38 | U216: 0 | AF216: 45594 | AG216: 320.65 | AH216: 330.33 | AI216: 323.95 | AJ216: -6.38 | AK216: 0
A217: 45593 | B217: 318.05 | C217: 331.1 | D217: 324.55 | E217: -6.56 | F217: 0 | P217: 45593 | Q217: 318.05 | R217: 331.1 | S217: 324.55 | T217: -6.56 | U217: 0 | AF217: 45593 | AG217: 318.05 | AH217: 331.1 | AI217: 324.55 | AJ217: -6.56 | AK217: 0
A218: 45590 | B218: 315.55 | C218: 332.15 | D218: 325.73 | E218: -6.42 | F218: 0 | P218: 45590 | Q218: 315.55 | R218: 332.15 | S218: 325.73 | T218: -6.42 | U218: 0 | AF218: 45590 | AG218: 315.55 | AH218: 332.15 | AI218: 325.73 | AJ218: -6.42 | AK218: 0
A219: 45589 | B219: 319.05 | C219: 333.47 | D219: 327.58 | E219: -5.9 | F219: 0 | P219: 45589 | Q219: 319.05 | R219: 333.47 | S219: 327.58 | T219: -5.9 | U219: 0 | AF219: 45589 | AG219: 319.05 | AH219: 333.47 | AI219: 327.58 | AJ219: -5.9 | AK219: 0
A220: 45588 | B220: 316.8 | C220: 334.63 | D220: 329.13 | E220: -5.5 | F220: 0 | P220: 45588 | Q220: 316.8 | R220: 334.63 | S220: 329.13 | T220: -5.5 | U220: 0 | AF220: 45588 | AG220: 316.8 | AH220: 334.63 | AI220: 329.13 | AJ220: -5.5 | AK220: 0
A221: 45587 | B221: 322.8 | C221: 336.05 | D221: 331.37 | E221: -4.69 | F221: 0 | P221: 45587 | Q221: 322.8 | R221: 336.05 | S221: 331.37 | T221: -4.69 | U221: 0 | AF221: 45587 | AG221: 322.8 | AH221: 336.05 | AI221: 331.37 | AJ221: -4.69 | AK221: 0
A222: 45586 | B222: 331 | C222: 337.12 | D222: 332.93 | E222: -4.19 | F222: 0 | P222: 45586 | Q222: 331 | R222: 337.12 | S222: 332.93 | T222: -4.19 | U222: 0 | AF222: 45586 | AG222: 331 | AH222: 337.12 | AI222: 332.93 | AJ222: -4.19 | AK222: 0
A223: 45583 | B223: 331.95 | C223: 337.6 | D223: 333.28 | E223: -4.33 | F223: 0 | P223: 45583 | Q223: 331.95 | R223: 337.6 | S223: 333.28 | T223: -4.33 | U223: 0 | AF223: 45583 | AG223: 331.95 | AH223: 337.6 | AI223: 333.28 | AJ223: -4.33 | AK223: 0
A224: 45582 | B224: 331.3 | C224: 338.06 | D224: 333.52 | E224: -4.54 | F224: 0 | P224: 45582 | Q224: 331.3 | R224: 338.06 | S224: 333.52 | T224: -4.54 | U224: 0 | AF224: 45582 | AG224: 331.3 | AH224: 338.06 | AI224: 333.52 | AJ224: -4.54 | AK224: 0
... A251: 45544 | B251: 328.55 | C251: 0 | D251: 0 | E251: 0 | F251: 0 | P251: 45544 | Q251: 328.55 | R251: 0 | S251: 0 | T251: 0 | U251: 0 | AF251: 45544 | AG251: 328.55 | AH251: 0 | AI251: 0 | AJ251: 0 | AK251: 0

Sheet Statement_Analysis
A2: Profitability Ratios | D2: Liquidity Ratios | G2: Leverage Ratios | K2: Efficinecy Ratios
A4: Gross Profit | B4: ='Income_Statement(5 years)'!F29/'Income_Statement(5 years)'!F7 -> 0.37057731 | D4: Current Ratio | E4: ='Balance_Sheet(5 years)'!F47/'Balance_Sheet(5 years)'!F21 -> 0.78411103 | G4: Debt to Equity | H4: ='Balance_Sheet(5 years)'!F54/'Balance_Sheet(5 years)'!F7 -> 1.4202032 | K4: COGS | L4: =FCFF_Projections!F4 -> 4314
A5: EBIT Margin | B5: =('Income_Statement(5 years)'!F20-'Income_Statement(5 years)'!F23)/'Income_Statement(5 years)'!F7 -> 0.6714248 | D5: Quick Ratio | E5: =('Balance_Sheet(5 years)'!F47-'Balance_Sheet(5 years)'!F41)/'Balance_Sheet(5 years)'!F21 -> 0.7494115 | G5: Interest Coverage | H5: =('Income_Statement(5 years)'!F20-'Income_Statement(5 years)'!F23)/'Income_Statement(5 years)'!F21 -> 2.9346124 | K5: Avg Inventory | L5: ='Balance_Sheet(5 years)'!F41 -> 1377.82
A6: ROE | B6: ='Income_Statement(5 years)'!F29/'Balance_Sheet(5 years)'!F7 -> 0.16649636 | D6: Cash Ratio | E6: ='Balance_Sheet(5 years)'!F43/'Balance_Sheet(5 years)'!F21 -> 0.16166853 | G6: Debt Ratio | H6: ='Balance_Sheet(5 years)'!F54/'Balance_Sheet(5 years)'!F52 -> 0.49594485 | K6: Inventory Turnover | L6: =L4/L5 -> 3.1310331
A7: ROA | B7: ='Income_Statement(5 years)'!F29/'Balance_Sheet(5 years)'!F52 -> 0.058141689 | K7: Receivables Turnover | L7: ='Income_Statement(5 years)'!F5/NWC!F3 -> 5.6964204
K8: Payables Turonver | L8: =L4/NWC!F8 -> 7.5993517
K9: Asset Turonver | L9: =FCFF_Projections!F3/'Balance_Sheet(5 years)'!F52 -> 0.1568949

Sheet Technical_Analysis
A2: Price & Volatility | F2: MACD
A3: Metric | B3: Power Grid | F3: Date | G3: Price (₹) | H3: MACD | I3: Signal | J3: Crossover
A4: 52W High (₹) | B4: 292.5 | F4: 2025-08-28 | G4: 284.5 | H4: 1.25 | I4: 1.05 | J4: BUY
A5: 52W Low (₹) | B5: 190.2 | F5: 2025-08-26 | G5: 283.2 | H5: 1.12 | I5: 1.01 | J5: BUY
A6: All-time High (₹) | B6: 292.5 | F6: 2025-08-25 | G6: 285.1 | H6: 0.98 | I6: 0.95 | J6: BUY
A7: All-time Low (₹) | B7: 90 | F7: 2025-08-22 | G7: 280.6 | H7: 0.67 | I7: 0.6 | J7: BUY
A8: Beta | B8: 0.48 | F8: 2025-08-21 | G8: 278.3 | H8: 0.45 | I8: 0.4 | J8: BUY
A9: Market Cap (₹ Cr) | B9: 230000 | F9: 2025-08-19 | G9: 272 | H9: -0.28 | I9: 0.5 | J9: SELL
A11: RSI | F11: ROC
A12: Date | B12: Price (₹) | C12: Volume | D12: RSI(14) | F12: Date | G12: Price (₹) | H12: ROC (%)
A13: 2025-08-28 | B13: 284.5 | C13: 1850000 | D13: 42.5 | F13: 2025-08-28 | G13: 284.5 | H13: 4.2
A14: 2025-08-26 | B14: 283.2 | C14: 1940000 | D14: 41.2 | F14: 2025-08-26 | G14: 283.2 | H14: 3.8
A15: 2025-08-25 | B15: 285.1 | C15: 2100000 | D15: 40.8 | F15: 2025-08-25 | G15: 285.1 | H15: 3.5
A16: 2025-08-22 | B16: 280.6 | C16: 1760000 | D16: 39.7 | F16: 2025-08-22 | G16: 280.6 | H16: 2.1
A17: 2025-08-21 | B17: 278.3 | C17: 1820000 | D17: 37.5 | F17: 2025-08-21 | G17: 278.3 | H17: 1.9
A18: 2025-08-14 | B18: 265 | C18: 1540000 | D18: 28.6 | F18: 2025-08-14 | G18: 265 | H18: -4.5
A19: 2025-08-13 | B19: 263.5 | C19: 1490000 | D19: 29.4 | F19: 2025-08-13 | G19: 263.5 | H19: -4.8
A20: 2025-08-12 | B20: 264.2 | C20: 1530000 | D20: 27.9
A21: 2025-08-11 | B21: 263.9 | C21: 1500000 | D21: 26.5 | F21: Analyst Targets
F22: Metric | G22: Power Grid
F23: Average Target (₹) | G23: 310
F24: Low Forecast (₹) | G24: 280
F25: High Forecast (₹) | G25: 345
F26: Analyst Consensus | G26: BUY

Sheet Balance_Sheet(5 years)
A1: Particulars | B1: Mar-2021 | C1: Mar-2022 | D1: Mar-2023 | E1: Mar-2024 | F1: Mar-2025
A3: EQUITY AND LIABILITIES
A4: Share Capital | B4: 5231.59 | C4: 6975.45 | D4: 6975.45 | E4: 9300.6 | F4: 9300.6
A5: Share Warrants & Outstandings | B5: 0 | C5: 0 | D5: 0 | E5: 0 | F5: 0
A6: Total Reserves | B6: 64347.25 | C6: 69176.12 | D6: 75868.73 | E6: 77566.45 | F6: 82915.05
A7: Shareholder's Funds | B7: 69578.84 | C7: 76151.57 | D7: 82844.18 | E7: 86867.05 | F7: 92215.65
A8: Long-Term Borrowings
A9: Secured Loans | B9: 90758.49 | C9: 81919.46 | D9: 74826.05 | E9: 64315.5 | F9: 56323.58
A10: Unsecured Loans | B10: 38321.58 | C10: 32279.94 | D10: 39065.24 | E10: 40751.45 | F10: 53534.37
A11: Deferred Tax Assets / Liabilities | B11: 11941.88 | C11: 11424.78 | D11: 10619.9 | E11: 9981.4 | F11: 10038.68
A12: Other Long Term Liabilities | B12: 13686.26 | C12: 13305.47 | D12: 13986.92 | E12: 12125.6 | F12: 11528.4
A13: Long Term Trade Payables
A14: Long Term Provisions | B14: 461.93 | C14: 517.05 | D14: 577.61 | E14: 643.11 | F14: 723.77
A15: Total Non-Current Liabilities | B15: 155170.14 | C15: 139446.7 | D15: 139075.72 | E15: 127817.06 | F15: 132148.8
A16: Current Liabilities
A17: Trade Payables | B17: 186.3 | C17: 266.14 | D17: 325.02 | E17: 354.07 | F17: 567.68
A18: Other Current Liabilities | B18: 26275.61 | C18: 25780.92 | D18: 22532.63 | E18: 27106.35 | F18: 26458.69
A19: Short Term Borrowings | B19: 1800 | C19: 5300 | D19: 2622.61 | E19: 2693.52 | F19: 5709.36
A20: Short Term Provisions | B20: 9899.84 | C20: 13137.1 | D20: 11996.06 | E20: 6758.67 | F20: 6971.44
A21: Total Current Liabilities | B21: 38161.75 | C21: 44484.16 | D21: 37476.32 | E21: 36912.61 | F21: 39707.17
A22: Liabilities as Held for Sale and Discontinued Operations
A23: Total Liabilities | B23: 262910.73 | C23: 260082.43 | D23: 259396.22 | E23: 251596.72 | F23: 264071.62
A24: ASSETS
A25: Non-Current Assets
A26: Gross Block | B26: 234284.32 | C26: 249953.7 | D26: 255823.8 | E26: 258805.36 | F26: 262459.74
A27: Less: Accumulated Depreciation | B27: 57340.82 | C27: 70221.94 | D27: 83546.25 | E27: 96104.85 | F27: 108824.88
A28: Less: Impairment of Assets
A29: Net Block | B29: 176943.5 | C29: 179731.76 | D29: 172277.55 | E29: 162700.51 | F29: 153634.86
A30: Lease Adjustment A/c
A31: Capital Work in Progress | B31: 17896.67 | C31: 7344.46 | D31: 7668.13 | E31: 9581.16 | F31: 12166.85
A32: Intangible assets under development | B32: 74.86 | C32: 31.53 | D32: 31.08 | E32: 91.01 | F32: 232.19
A33: Pre-operative Expenses pending
A34: Assets in transit | B34: 0.03 | E34: 1.84 | F34: 1.87
A35: Non Current Investments | B35: 4265.36 | C35: 7228.53 | D35: 7414.95 | E35: 8731.63 | F35: 11312.3
A36: Long Term Loans & Advances | B36: 10943.69 | C36: 14762.33 | D36: 18673.71 | E36: 22713.55 | F36: 36915.78
A37: Other Non Current Assets | B37: 19194.93 | C37: 18422.68 | D37: 18919.33 | E37: 18281.3 | F37: 18672.94
A38: Total Non-Current Assets | B38: 229319.04 | C38: 227521.29 | D38: 224984.75 | E38: 222101 | F38: 232936.79
A39: Current Assets Loans & Advances
A40: Currents Investments | B40: 952.18 | C40: 15.86 | D40: 260.86 | E40: 869.12
A41: Inventories | B41: 1362.82 | C41: 1352.6 | D41: 1323.55 | E41: 1303.73 | F41: 1377.82
...

Sheet Income_Statement(5 years)
A1: Particulars | B1: Mar-2021 | C1: Mar-2022 | D1: Mar-2023 | E1: Mar-2024 | F1: Mar-2025
A3: No of Months | B3: 12 | C3: 12 | D3: 12 | E3: 12 | F3: 12
A4: INCOME :
A5: Operating Income | B5: 37665.65 | C5: 39933.39 | D5: 42635.9 | E5: 42391.16 | F5: 41431.49
A6: Less: Excise / GST
A7: Net Sales | B7: 37665.65 | C7: 39933.39 | D7: 42635.9 | E7: 42391.16 | F7: 41431.49
A8: EXPENDITURE :
A9: Increase/Decrease in Stock
A10: Power Generation & Distribution Cost | B10: 264.67 | C10: 297 | D10: 304.95 | E10: 317.61 | F10: 329.82
A11: Employee Cost | B11: 2110.74 | C11: 2234.76 | D11: 2400.35 | E11: 2376.88 | F11: 2593
A12: Operating Expenses | B12: 1029.62 | C12: 1163.69 | D12: 1001.73 | E12: 1172.53 | F12: 1391.18
A13: General and Administration Expenses | B13: 743.48 | C13: 828.5 | D13: 846.29 | E13: 930.61 | F13: 936.79
A14: Selling and Distribution Expenses | B14: 7.65 | C14: 10.77 | D14: 17.92 | E14: 14.54 | F14: 53.07
A15: Miscellaneous Expenses | B15: 453.67 | C15: 472.6 | D15: 1103.97 | E15: 824.88 | F15: 853.35
A16: Less: Expenses Capitalised
A17: Total Expenditure | B17: 4609.83 | C17: 5007.32 | D17: 5675.21 | E17: 5637.05 | F17: 6157.21
A18: Operating Profit (Excl OI) | B18: 33055.82 | C18: 34926.07 | D18: 36960.69 | E18: 36754.11 | F18: 35274.28
A19: Other Income | B19: 3084.68 | C19: 2403.42 | D19: 2591.98 | E19: 3424.92 | F19: 4896.08
A20: Operating Profit | B20: 36140.5 | C20: 37329.49 | D20: 39552.67 | E20: 40179.03 | F20: 40170.36
A21: Interest | B21: 8724.11 | C21: 8210.94 | D21: 9707.2 | E21: 9046.87 | F21: 9479.32
A22: PBDT | B22: 27416.39 | C22: 29118.55 | D22: 29845.47 | E22: 31132.16 | F22: 30691.04
A23: Depreciation | B23: 11711.68 | C23: 12550.58 | D23: 12858.52 | E23: 12558.19 | F23: 12352.23
A24: Profit Before Taxation & Exceptional Items | B24: 15704.71 | C24: 16567.97 | D24: 16986.95 | E24: 18573.97 | F24: 18338.81
A25: Share of Profit/Loss of JV & Associates
A26: Exceptional Income / Expenses | B26: -679.79 | C26: 3236.85 | D26: 256.43 | E26: -564.51 | F26: 280.62
A27: Profit Before Tax | B27: 15024.92 | C27: 19804.82 | D27: 17243.38 | E27: 18009.46 | F27: 18619.43
A28: Provision for Tax | B28: 3089.14 | C28: 2711.06 | D28: 2118.84 | E28: 2631.98 | F28: 3265.86
A29: Profit After Tax | B29: 11935.78 | C29: 17093.76 | D29: 15124.54 | E29: 15377.48 | F29: 15353.57
A30: Discontinued Operations
A31: Profit Before Tax from Discontinued Operations | D31: 227.74 | E31: 116.27
A32: Tax from Discontinued Operations | D32: 16.74 | E32: 19.14
A33: Profit After Tax from Discontinued Operations | D33: 211 | E33: 97.13
A34: Extra items
A35: Adjustments to PAT
A36: Profit Balance B/F | B36: 3327.57 | C36: 3399.08 | D36: 4119.59 | E36: 3262.91 | F36: 2013.52
A37: Appropriations | B37: 15263.35 | C37: 20492.84 | D37: 19455.13 | E37: 18737.52 | F37: 17367.09
A38: Equity Dividend % | B38: 120 | C38: 147.5 | D38: 147.5 | E38: 112.5 | F38: 90
A39: Earnings Per Share(Calculated) | B39: 22.81 | C39: 24.51 | D39: 21.68 | E39: 16.53 | F39: 16.51
A40: Adjusted EPS | B40: 12.83 | C40: 18.38 | D40: 16.26 | E40: 16.53 | F40: 16.51
A41: EPS - Basic (Reported) | B41: 17.11 | C41: 24.51 | D41: 16.49 | E41: 16.64 | F41: 16.51
...

Sheet Balance_Sheet
A1: Power Grid Corporation Of India Ltd. - Balance Sheet - Standalone-Abridged-Actual - [INR-Crores]
